<?xml version="1.0"?>
<robot xmlns:xacro="http://www.ros.org/wiki/xacro" name="beginner_tutorials">

<!-- An example of a simple robot with 4 wheels and a body -->

<link name="base_footprint"/>

<!-- initializing base link -->
<link name="base_link">
    <inertial>
        <origin xyz="0.0 0.0 0.0" rpy="0.0 0.0 0.0"/>
        <mass value="1"/>
        <inertia ixx="0.4" ixy="0.0" ixz="0.0" iyy="0.2" iyz="0.0" izz="0.4"/>
    </inertial>
    
    
    <visual>
        <origin xyz="0.0 0.0 0" rpy="0.0 0.0 0.0"/>

        <geometry>
            <box size="0.8 0.7 0.1" />
        </geometry>
         
        <material name="black">
            <color rgba="1 0.3 0.5 0.6"/>
        </material>
    </visual>

    <collision>
        
    
        <origin xyz="0.0 0.0 0" rpy="0.0 0.0 0.0"/>

        <geometry>
            <box size="0.9 0.8 0.2" />
        </geometry>
    </collision>
    
</link>

<!-- joint between base link and footprint -->
<joint name="base_joint" type="fixed">
    <parent link="base_footprint"/>
    <child link="base_link"/>
    <origin xyz="0 0 0.135" rpy="0 0 0"/>
    <axis xyz="0 0 0"/>
</joint>


<xacro:macro name="wheel" params="name x y z">

    <link name="wheel_${name}_link">
        <inertial>
            <origin xyz="0.0 0.0 0.0" rpy="0.0 0.0 0.0"/>
            <mass value="0.5"/>
            <inertia ixx="0.0" ixy="0.0" ixz="0.0" iyy="0.0" iyz="0.0" izz="0.0"/>
        </inertial>
        
        <visual>
            <origin xyz="0.0 0.0 0.0" rpy="0.0 0.0 0.0"/>
            <geometry> 
                <cylinder radius="0.15" length="0.1"/>
            </geometry>
            <material name="LightGrey">
                <color rgba="0.7 0.7 0.7 1.0"/>
            </material>
        </visual>

        <collision>
            <origin xyz="0.0 0.0 0.0" rpy="0.0 0.0 0.0"/>
            <geometry> 
                <cylinder radius="0.16" length="0.2"/>
            </geometry>
        
        </collision>

    </link>

    <joint name="wheel_${name}_joint" type="continuous">
        <parent link="base_link"/>
        <child link="wheel_${name}_link"/>
        <origin xyz="${x} ${y} ${z}" rpy="1.57 0 0"/>
        <axis xyz="0 0 1"/>
    </joint>
    
</xacro:macro>

<xacro:wheel name="front_left" x="0.25" y="0.4" z="0">
</xacro:wheel>

<xacro:wheel name="front_right" x="0.25" y="-0.4" z="0">
</xacro:wheel>

<xacro:wheel name="rear_left" x="-0.25" y="0.4" z="0">
</xacro:wheel>

<xacro:wheel name="rear_right" x="-0.25" y="-0.4" z="0">
</xacro:wheel>


<xacro:include filename="$(find beginner_tutorials)/gazebo/bot.gazebo" />

</robot>